Workbook

Sheet Contents
A1: Education at a Glance 2018: OECD Indicators - © OECD 2018
A2: D | B2: Indicator D4. How much time do teachers spend teaching?
A3: Version 2 - Last updated: 05-Sep-2018
A4: Disclaimer: http://oe.cd/disclaimer
A6: Education at a Glance 2018
A7: Indicator D4: How much time do teachers spend teaching?
A9: Tables
A10: Table D4.1. | B10: Organisation of teachers' working time (2017)
A11: Table D4.2. | B11: Number of teaching hours per year (2000, 2005 to 2017)
A12: Table D4.3. | B12: Tasks and responsibilities of teachers, by level of education (2017)
A14: Figures
A15: Figure D4.1. | B15: Number of teaching hours per year in general lower secondary education (2000, 2005 and 2017)
A16: Figure D4.2. | B16: Number of teaching hours per year, by level of education (2017)
A17: Figure D4.3. | B17: Number of teaching hours per year in general and vocational programmes at upper secondary level (2017)
A18: Figure D4.4. | B18: Percentage of lower secondary teachers' working time spent teaching (2017)
A19: Figure D4.5 (Web only). | B19: Actual and statutory teaching time in general lower secondary education (2016)
A21: Box
A22: Figure D4.a | B22: Tasks and responsibilities lower secondary teachers are required to perform (2017)
A25: © OECD 2018
A27: Symbols for missing data
A28: m | B28: Data are not available
A29: a | B29: Data are not applicable because the category does not apply
A30: x | B30: Data included in another category
A31: d | B31: Includes data from another category
A32: 0 | B32: Magnitude is either negligible or zero
A33: b | B33: Break in the time series

Sheet Table D4.1.
A1: Education at a Glance 2018: OECD Indicators - © OECD 2018
A2: D | B2: Indicator D4. How much time do teachers spend teaching?
A3: Version 2 - Last updated: 05-Sep-2018
A4: Disclaimer: http://oe.cd/disclaimer
A6: Table D4.1.
A7: Organisation of teachers' working time (2017)
A8: Number of statutory teaching weeks, teaching days, net teaching hours and teachers' working time in public institutions over the school year
B10: Notes | C10: Number of weeks of teaching | O10: Number of days of teaching | AA10: Net teaching time, in hours | AM10: Working time required at school, in hours | AY10: Total statutory working time, in hours
C11: Pre-primary | E11: Primary | G11: Lower secondary, general programmes | I11: Lower secondary, vocational programmes | K11: Upper secondary, general programmes | M11: Upper secondary, vocational programmes | O11: Pre-primary | Q11: Primary | S11: Lower secondary, general programmes | U11: Lower secondary, vocational programmes | W11: Upper secondary, general programmes | Y11: Upper secondary, vocational programmes | AA11: Pre-primary | AC11: Primary | AE11: Lower secondary, general programmes | AG11: Lower secondary, vocational programmes | AI11: Upper secondary, general programmes | AK11: Upper secondary, vocational programmes | AM11: Pre-primary | AO11: Primary | AQ11: Lower secondary, general programmes | AS11: Lower secondary, vocational programmes | AU11: Upper secondary, general programmes | AW11: Upper secondary, vocational programmes | AY11: Pre-primary | BA11: Primary | BC11: Lower secondary, general programmes | BE11: Lower secondary, vocational programmes | BG11: Upper secondary, general programmes | BI11: Upper secondary, vocational programmes
C12: 1 | E12: 2 | G12: 3 | I12: 4 | K12: 5 | M12: 6 | O12: 7 | Q12: 8 | S12: 9 | U12: 10 | W12: 11 | Y12: 12 | AA12: 13 | AC12: 14 | AE12: 15 | AG12: 16 | AI12: 17 | AK12: 18 | AM12: 19 | AO12: 20 | AQ12: 21 | AS12: 22 | AU12: 23 | AW12: 24 | AY12: 25 | BA12: 26 | BC12: 27 | BE12: 28 | BG12: 29 | BI12: 30
A13: OECD
A14: Countries
A15: Australia | B15: 1 | C15: 40.000004 | E15: 40.36795 | G15: 40.368896 | J15: m | K15: 40.368896 | N15: m | O15: 197.55507 | Q15: 195.07356 | S15: 195.09894 | V15: m | W15: 195.09894 | Z15: m | AA15: 903.24667 | AC15: 865.2686 | AE15: 797.28162 | AH15: m | AI15: 797.28162 | AL15: m | AM15: 1243.4473 | AO15: 1241.8278 | AQ15: 1239.1869 | AT15: m | AU15: 1239.1869 | AX15: m | AZ15: a | BB15: a | BD15: a | BF15: a | BH15: a | BJ15: a
A16: Austria | B16: 1 | D16: m | E16: 38 | G16: 38 | J16: a | K16: 38 | N16: m | P16: m | Q16: 180 | S16: 180 | V16: a | W16: 180 | Z16: m | AB16: m | AC16: 779.4 | AE16: 606.6 | AH16: a | AI16: 588.6 | AL16: m | AN16: m | AP16: a | AR16: a | AT16: a | AV16: a | AX16: a | AZ16: a | BA16: 1776 | BC16: 1776 | BF16: a | BH16: a | BJ16: a
A17: Canada | B17: 1 | D17: m | E17: 36.563326 | G17: 36.563326 | I17: 40 | K17: 36.563326 | M17: 40 | P17: m | Q17: 182.81663 | S17: 182.81663 | U17: 200 | W17: 182.81663 | Y17: 200 | AB17: m | AC17: 797.7713 | AE17: 744.53292 | AG17: 635 | AI17: 745.74031 | AK17: 635 | AN17: m | AO17: 1228.2119 | AQ17: 1233.3686 | AS17: 1280 | AU17: 1236.3154 | AW17: 1280 | AZ17: m | BB17: a | BD17: a | BE17: 1280 | BH17: a | BI17: 1280
A18: Chile | B18: 2 | C18: 38 | E18: 38 | G18: 38 | J18: a | K18: 38 | M18: 38 | O18: 178 | Q18: 178 | S18: 178 | V18: a | W18: 178 | Y18: 178 | AA18: 1063.5552 | AC18: 1063.5552 | AE18: 1063.5552 | AH18: a | AI18: 1063.5552 | AK18: 1063.5552 | AM18: 1830.4 | AO18: 1830.4 | AQ18: 1830.4 | AT18: a | AU18: 1830.4 | AW18: 1830.4 | AY18: 1962.4 | BA18: 1962.4 | BC18: 1962.4 | BF18: a | BG18: 1962.4 | BI18: 1962.4
A19: Czech Republic | B19: 1 | C19: 45 | E19: 39 | G19: 39 | I19: 39 | K19: 39 | M19: 39 | O19: 215 | Q19: 187 | S19: 187 | U19: 187 | W19: 187 | Y19: 187 | AA19: 1333 | AC19: 617.1 | AE19: 617.1 | AG19: 617.1 | AI19: 589.05 | AK19: 589.05 | AN19: a | AP19: a | AR19: a | AT19: a | AV19: a | AX19: a | AY19: 1800 | BA19: 1560 | BC19: 1560 | BE19: 1560 | BG19: 1560 | BI19: 1560
A20: Denmark | D20: a | F20: a | H20: a | J20: a | L20: a | N20: a | P20: a | R20: a | T20: a | V20: a | X20: a | Z20: a | AB20: a | AD20: a | AF20: a | AH20: a | AI20: 405 | AK20: 615 | AN20: a | AP20: a | AR20: a | AT20: a | AV20: a | AX20: a | AY20: 1680 | BA20: 1680 | BC20: 1680 | BE20: 1680 | BG20: 1680 | BI20: 1680
A21: Estonia | B21: 1 | C21: 46 | E21: 35 | G21: 35 | I21: 40 | K21: 35 | M21: 40 | O21: 220 | Q21: 172 | S21: 172 | U21: 195 | W21: 172 | Y21: 195 | AA21: 1320 | AC21: 584.8 | AE21: 602 | AH21: a | AI21: 567.6 | AL21: a | AM21: 1610 | AP21: a | AR21: a | AT21: a | AV21: a | AX21: a | AY21: 1610 | BA21: 1540 | BC21: 1540 | BE21: 1540 | BG21: 1540 | BI21: 1540
A22: Finland | B22: 3 | D22: m | E22: 38 | G22: 38 | J22: a | K22: 38 | M22: 38 | P22: m | Q22: 187 | S22: 187 | V22: a | W22: 187 | Y22: 187 | AB22: m | AC22: 673.2 | AE22: 589.05 | AH22: a | AI22: 547.162 | AK22: 688.16 | AN22: m | AO22: 787.2 | AQ22: 703 | AT22: a | AU22: 642.2 | AW22: 769.2 | AZ22: a | BB22: a | BD22: a | BF22: a | BH22: a | BJ22: a
A23: France | B23: 1 | C23: 36 | E23: 36 | G23: 36 | I23: 36 | K23: 36 | M23: 36 | O23: 162 | Q23: 162 | T23: a | V23: a | X23: a | Z23: a | AA23: 900 | AC23: 900 | AE23: 684 | AG23: 684 | AI23: 684 | AK23: 684 | AM23: 954 | AO23: 954 | AR23: a | AT23: a | AV23: a | AX23: a | AY23: 1607 | BA23: 1607 | BC23: 1607 | BE23: 1607 | BG23: 1607 | BI23: 1607
A24: Germany | B24: 1 | C24: 46 | E24: 39.5 | G24: 39.5 | J24: a | K24: 39.5 | M24: 39.5 | O24: 225 | Q24: 192.5 | S24: 192.5 | V24: a | W24: 192.5 | Y24: 192.5 | AA24: 1755 | AC24: 800.53659 | AE24: 747.40942 | AH24: a | AI24: 719.32344 | AK24: 726.1909 | AN24: a | AP24: a | AR24: a | AT24: a | AV24: a | AX24: a | AY24: 1781.5 | BA24: 1781.5 | BC24: 1781.5 | BF24: a | BG24: 1781.5 | BI24: 1781.5
A25: Greece | B25: 2 | C25: 35.8 | E25: 35.8 | G25: 35.9 | J25: a | K25: 35.03 | M25: 35.03 | O25: 176 | Q25: 176 | S25: 176.5 | V25: a | W25: 172.15 | Y25: 172.15 | AA25: 821.92 | AC25: 660 | AE25: 608.925 | AH25: a | AI25: 593.9175 | AK25: 593.9175 | AM25: 1134 | AO25: 1134 | AQ25: 1176 | AT25: a | AU25: 1176 | AW25: 1176 | AZ25: a | BB25: a | BD25: a | BF25: a | BH25: a | BJ25: a
A26: Hungary | B26: 3 | C26: 43.4 | E26: 38 | G26: 38 | I26: 38 | K26: 38 | M26: 38 | O26: 210 | Q26: 182 | S26: 182 | U26: 181 | W26: 181 | Y26: 181 | AA26: 1344 | AC26: 655.2 | AE26: 655.2 | AG26: 651.6 | AI26: 651.6 | AK26: 651.6 | AM26: 1512 | AO26: 1164.8 | AQ26: 1164.8 | AS26: 1158.4 | AU26: 1158.4 | AW26: 1158.4 | AY26: 1664 | BA26: 1664 | BC26: 1664 | BE26: 1664 | BG26: 1664 | BI26: 1664
A27: Iceland | C27: 46 | E27: 37 | G27: 37 | J27: a | K27: 36 | M27: 36 | O27: 225 | Q27: 180 | S27: 180 | V27: a | W27: 175 | Y27: 175 | AA27: 1620 | AC27: 623.88 | AE27: 623.88 | AH27: a | AI27: 485.39326 | AK27: 508.23529 | AM27: 1760 | AO27: 1610 | AQ27: 1610 | AT27: a | AU27: 1440 | AW27: 1440 | AY27: 1760 | BA27: 1760 | BC27: 1760 | BF27: m | BG27: 1800 | BI27: 1800
A28: Ireland | B28: 1 | D28: m | E28: 36.6 | G28: 32.8 | J28: a | K28: 32.8 | N28: m | P28: m | Q28: 182 | S28: 164 | V28: a | W28: 164 | Z28: m | AB28: m | AC28: 910 | AE28: 721.6 | AH28: a | AI28: 721.6 | AL28: m | AN28: m | AO28: 1073 | AQ28: 810.8 | AT28: a | AU28: 810.8 | AX28: m | AZ28: a | BB28: a | BD28: a | BF28: a | BH28: a | BJ28: a
A29: Israel | B29: 1 | C29: 37.451503 | E29: 37.451503 | G29: 36.088253 | I29: 36.088253 | K29: 36.088253 | M29: 36.088253 | O29: 182.25751 | Q29: 182.25751 | S29: 175.44127 | U29: 175.44127 | W29: 173.44127 | Y29: 173.44127 | AA29: 1030.7533 | AC29: 843.34742 | AE29: 698.87171 | AG29: 698.87171 | AI29: 609.74472 | AK29: 609.74472 | AM29: 1067.2048 | AO29: 1236.2151 | AQ29: 1181.2124 | AS29: 1181.2124 | AU29: 1166.2525 | AW29: 1166.2525 | AY29: 1067.2048 | BA29: 1236.2151 | BC29: 1181.2124 | BE29: 1181.2124 | BG29: 1166.2525 | BI29: 1166.2525
A30: Italy | B30: 1 | C30: 42 | E30: 39 | G30: 39 | J30: a | K30: 39 | M30: 39 | O30: 189 | Q30: 174 | S30: 174 | V30: a | W30: 174 | Y30: 174 | AA30: 945 | AC30: 765.6 | AE30: 626.4 | AH30: a | AI30: 626.4 | AK30: 626.4 | AN30: a | AP30: a | AR30: a | AT30: a | AV30: a | AX30: a | AZ30: a | BB30: a | BD30: a | BF30: a | BH30: a | BJ30: a
A31: Japan | B31: 4 | D31: m | E31: 40.222 | G31: 40.213 | J31: a | K31: 39.289 | M31: 39.289 | P31: m | Q31: 201.11 | S31: 201.065 | V31: a | W31: 196.445 | Y31: 196.445 | AB31: m | AC31: 742.0959 | AE31: 609.91057 | AH31: a | AI31: 510.757 | AK31: 510.757 | AN31: a | AP31: a | AR31: a | AT31: a | AV31: a | AX31: a | AY31: 1883 | BA31: 1883 | BC31: 1883 | BE31: 1883 | BG31: 1883 | BI31: 1883
A32: Korea | B32: 3 | C32: 36 | E32: 38 | G32: 38 | J32: a | K32: 38 | M32: 38 | O32: 180 | Q32: 190 | S32: 190 | V32: a | W32: 190 | Y32: 190 | AA32: 543.49756 | AC32: 671.13441 | AE32: 533.23146 | AH32: a | AI32: 550.72526 | AK32: 557.01141 | AN32: a | AP32: a | AR32: a | AT32: a | AV32: a | AX32: a | AY32: 1520 | BA32: 1520 | BC32: 1520 | BE32: 1520 | BG32: 1520 | BI32: 1520
A33: Latvia | B33: 1 | C33: 39 | E33: 35 | G33: 35 | I33: 44 | K33: 35 | M33: 44 | O33: 190 | Q33: 170 | S33: 170 | U33: 215 | W33: 170 | Y33: 215 | AA33: 1520 | AC33: 1020 | AE33: 1020 | AG33: 1290 | AI33: 1020 | AK33: 1290 | AM33: 1560 | AO33: 1050 | AQ33: 1050 | AS33: 1320 | AU33: 1050 | AW33: 1320 | AY33: 1760 | BA33: 1760 | BC33: 1760 | BE33: 1760 | BG33: 1760 | BI33: 1760
A34: Luxembourg | B34: 1 | D34: m | F34: m | H34: m | J34: m | L34: m | N34: m | P34: m | R34: m | T34: m | V34: m | X34: m | Z34: m | AB34: m | AD34: m | AF34: m | AH34: m | AJ34: m | AL34: m | AN34: m | AP34: m | AR34: m | AT34: m | AV34: m | AX34: m | AZ34: m | BB34: m | BD34: m | BF34: m | BH34: m | BJ34: m
A35: Mexico | B35: 1 | C35: 41.8 | E35: 41.8 | G35: 41.8 | I35: 41.8 | K35: 36 | M35: 36 | O35: 200 | Q35: 200 | S35: 200 | U35: 200 | W35: 171 | Y35: 171 | AA35: 532 | AC35: 800 | AE35: 1046.6667 | AG35: 800 | AI35: 837.9 | AK35: 684 | AM35: 772 | AO35: 800 | AQ35: 1167 | AS35: 800 | AU35: 970.9 | AW35: 692 | AZ35: a | BB35: a | BD35: a | BF35: a | BH35: a | BJ35: a
A36: Netherlands | B36: 2 | C36: 40 | E36: 40 | H36: m | J36: m | L36: m | N36: m | O36: 200 | Q36: 200 | T36: m | V36: m | X36: m | Z36: m | AA36: 930 | AC36: 930 | AE36: 750 | AG36: 750 | AI36: 750 | AL36: m | AN36: a | AP36: a | AR36: a | AT36: a | AV36: a | AX36: a | AY36: 1659 | BA36: 1659 | BC36: 1659 | BE36: 1659 | BG36: 1659 | BI36: 1659
A37: New Zealand | B37: 1 | D37: m | E37: 38.4 | G37: 38.2 | J37: a | K37: 38 | N37: m | P37: m | Q37: 192 | S37: 191 | V37: a | W37: 190 | Z37: m | AB37: m | AC37: 921.6 | AE37: 840.4 | AH37: a | AI37: 760 | AL37: m | AN37: m | AO37: 1536 | AQ37: 1243 | AT37: a | AU37: 950 | AX37: m | AZ37: a | BB37: a | BD37: a | BF37: a | BH37: a | BJ37: a
A38: Norway | B38: 2 | C38: 45 | E38: 38 | G38: 38 | J38: a | K38: 38 | M38: 38 | O38: 225 | Q38: 190 | S38: 190 | V38: a | W38: 190 | Y38: 190 | AB38: a | AC38: 741 | AE38: 663.1 | AH38: a | AI38: 522.5 | AK38: 522.5 | AN38: a | AO38: 1300 | AQ38: 1225 | AT38: a | AU38: 1150 | AW38: 1150 | AY38: 1687.5 | BA38: 1687.5 | BC38: 1687.5 | BF38: a | BG38: 1687.5 | BI38: 1687.5
A39: Poland | B39: 1 | C39: 45.2 | E39: 37.4 | G39: 37 | J39: a | K39: 36.6 | M39: 36.6 | O39: 217 | Q39: 179 | S39: 177 | V39: a | W39: 175 | Y39: 175 | AA39: 1085 | AC39: 563.85 | AE39: 477.9 | AH39: a | AI39: 472.5 | AK39: 472.5 | AN39: m | AP39: m | AR39: m | AT39: a | AV39: m | AX39: m | AY39: 1808 | BA39: 1496 | BC39: 1480 | BF39: a | BG39: 1464 | BI39: 1464
A40: Portugal | B40: 2 | C40: 41 | E40: 39 | G40: 38 | I40: 38 | K40: 38 | M40: 38 | O40: 187 | Q40: 173 | S40: 168 | U40: 168 | W40: 168 | Y40: 168 | AA40: 935 | AC40: 778.5 | AE40: 616 | AG40: 616 | AI40: 616 | AK40: 616 | AM40: 1085.8 | AO40: 1038.2 | AQ40: 920.4 | AS40: 920.4 | AU40: 920.4 | AW40: 920.4 | AY40: 1572 | BA40: 1488 | BC40: 1458 | BE40: 1458 | BG40: 1458 | BI40: 1458
A41: Slovak Republic | B41: 1 | C41: 44.2 | E41: 39.2 | G41: 39.2 | I41: 39.2 | K41: 39.2 | M41: 39.2 | O41: 209 | Q41: 189 | S41: 189 | U41: 189 | W41: 189 | Y41: 189 | AA41: 1149.5 | AC41: 793.8 | AE41: 652.05 | AG41: 623.7 | AI41: 567 | AK41: 604.8 | AN41: m | AP41: m | AR41: m | AT41: m | AV41: m | AX41: m | AY41: 1567.5 | BA41: 1567.5 | BC41: 1567.5 | BE41: 1567.5 | BG41: 1567.5 | BI41: 1567.5
A42: Slovenia | B42: 1 | C42: 46 | E42: 38 | G42: 38 | J42: a | K42: 38 | M42: 38 | O42: 219 | Q42: 190 | S42: 190 | V42: a | W42: 190 | Y42: 190 | AA42: 1314 | AC42: 627 | AE42: 627 | AH42: a | AI42: 570 | AK42: 570 | AN42: a | AP42: a | AR42: a | AT42: a | AV42: a | AX42: a | AZ42: m | BB42: m | BD42: m | BF42: m | BH42: m | BJ42: m
...

Sheet Table D4.2.
A1: Education at a Glance 2018: OECD Indicators - © OECD 2018
A2: D | B2: Indicator D4. How much time do teachers spend teaching?
A3: Version 2 - Last updated: 05-Sep-2018
A4: Disclaimer: http://oe.cd/disclaimer
A6: Table D4.2.
A7: Number of teaching hours per year (2000, 2005 to 2017)
A8: Net statutory contact time in public institutions, by level of education
B10: Notes | C10: Pre-primary | AE10: Primary | BG10: Lower secondary, general programmes | CI10: Upper secondary, general programmes
C11: 2000 | E11: 2005 | G11: 2006 | I11: 2007 | K11: 2008 | M11: 2009 | O11: 2010 | Q11: 2011 | S11: 2012 | U11: 2013 | W11: 2014 | Y11: 2015 | AA11: 2016 | AC11: 2017 | AE11: 2000 | AG11: 2005 | AI11: 2006 | AK11: 2007 | AM11: 2008 | AO11: 2009 | AQ11: 2010 | AS11: 2011 | AU11: 2012 | AW11: 2013 | AY11: 2014 | BA11: 2015 | BC11: 2016 | BE11: 2017 | BG11: 2000 | BI11: 2005 | BK11: 2006 | BM11: 2007 | BO11: 2008 | BQ11: 2009 | BS11: 2010 | BU11: 2011 | BW11: 2012 | BY11: 2013 | CA11: 2014 | CC11: 2015 | CE11: 2016 | CG11: 2017 | CI11: 2000 | CK11: 2005 | CM11: 2006 | CO11: 2007 | CQ11: 2008 | CS11: 2009 | CU11: 2010 | CW11: 2011 | CY11: 2012 | DA11: 2013 | DC11: 2014 | DE11: 2015 | DG11: 2016 | DI11: 2017
C12: 1 | E12: 2 | G12: 3 | I12: 4 | K12: 5 | M12: 6 | O12: 7 | Q12: 8 | S12: 9 | U12: 10 | W12: 11 | Y12: 12 | AA12: 13 | AC12: 14 | AE12: 15 | AG12: 16 | AI12: 17 | AK12: 18 | AM12: 19 | AO12: 20 | AQ12: 21 | AS12: 22 | AU12: 23 | AW12: 24 | AY12: 25 | BA12: 26 | BC12: 27 | BE12: 28 | BG12: 29 | BI12: 30 | BK12: 31 | BM12: 32 | BO12: 33 | BQ12: 34 | BS12: 35 | BU12: 36 | BW12: 37 | BY12: 38 | CA12: 39 | CC12: 40 | CE12: 41 | CG12: 42 | CI12: 43 | CK12: 44 | CM12: 45 | CO12: 46 | CQ12: 47 | CS12: 48 | CU12: 49 | CW12: 50 | CY12: 51 | DA12: 52 | DC12: 53 | DE12: 54 | DG12: 55 | DI12: 56
A13: OECD
A14: Countries
A15: Australia | D15: m | F15: m | H15: m | J15: m | L15: m | N15: m | P15: m | Q15: 884.87662 | S15: 883.66121 | U15: 904.15804 | W15: 885.18347 | Y15: 882.14931 | AA15: 859.55436 | AC15: 903.24667 | AE15: 882.35232 | AG15: 888.3 | AI15: 884.33204 | AK15: 876.93202 | AM15: 872.55573 | AO15: 874.37937 | AQ15: 868.15076 | AS15: 872.54543 | AU15: 871.28204 | AW15: 879.2071 | AY15: 871.9632 | BA15: 865.76544 | BC15: 862.45697 | BE15: 865.2686 | BG15: 810.54626 | BI15: 810.16 | BK15: 818.47444 | BM15: 814.54896 | BO15: 811.81839 | BQ15: 812.29372 | BS15: 819.16515 | BU15: 810.80546 | BW15: 808.58901 | BY15: 821.30038 | CA15: 811.62817 | CC15: 805.97951 | CE15: 795.38401 | CG15: 797.28162 | CI15: 803.42575 | CK15: 810.16 | CM15: 817.04836 | CO15: 813.15905 | CQ15: 810.4379 | CS15: 797.05472 | CU15: 803.25933 | CW15: 802.16714 | CY15: 801.32556 | DA15: 812.3237 | DC15: 804.01312 | DE15: 804.48307 | DG15: 795.84434 | DI15: 797.28162
A16: Austria | B16: 1 | D16: m | E16: 774 | G16: 774 | I16: 774 | K16: 779.4 | M16: 779.4 | O16: 779.4 | Q16: 779.4 | S16: 779.4 | U16: 779.4 | X16: m | Z16: m | AB16: m | AD16: m | AF16: m | AG16: 774 | AI16: 774 | AK16: 774 | AM16: 779.4 | AO16: 779.4 | AQ16: 779.4 | AS16: 779.4 | AU16: 779.4 | AW16: 779.4 | AY16: 779.4 | BA16: 779.4 | BC16: 779.4 | BE16: 779.4 | BH16: m | BI16: 606.6 | BK16: 606.6 | BM16: 606.6 | BO16: 606.6 | BQ16: 606.6 | BS16: 606.6 | BU16: 606.6 | BW16: 606.6 | BY16: 606.6 | CA16: 606.6 | CC16: 606.6 | CE16: 606.6 | CG16: 606.6 | CJ16: m | CK16: 588.6 | CM16: 588.6 | CO16: 588.6 | CQ16: 588.6 | CS16: 588.6 | CU16: 588.6 | CW16: 588.6 | CY16: 588.6 | DA16: 588.6 | DC16: 588.6 | DE16: 588.6 | DG16: 588.6 | DI16: 588.6
A17: Canada | D17: m | F17: m | H17: m | J17: m | L17: m | N17: m | P17: m | R17: m | T17: m | V17: m | X17: m | Z17: m | AB17: m | AD17: m | AF17: m | AH17: m | AJ17: m | AL17: m | AN17: m | AP17: m | AQ17: 799.31288 | AS17: 799.26561 | AU17: 799 | AW17: 795.85984 | AY17: 796 | BA17: 797.04658 | BC17: 797.7713 | BE17: 797.7713 | BH17: m | BJ17: m | BL17: m | BN17: m | BP17: m | BR17: m | BS17: 740.37249 | BU17: 743.20816 | BW17: 744 | BY17: 743.31383 | CA17: 743 | CC17: 741.85087 | CE17: 744.53292 | CG17: 744.53292 | CJ17: m | CL17: m | CN17: m | CP17: m | CR17: m | CT17: m | CU17: 744.16763 | CW17: 747.00308 | CY17: 747 | DA17: 744.63642 | DC17: 744 | DE17: 742.97258 | DG17: 745.74031 | DI17: 745.74031
A18: Chile | D18: m | F18: m | H18: m | J18: m | L18: m | N18: m | P18: m | Q18: 1119.9822 | S18: 1103.3428 | U18: 1128.5562 | W18: 1145.8134 | Y18: 1157.36 | AA18: 1158.4305 | AC18: 1063.5552 | AF18: m | AG18: 1127.6856 | AI18: 1100.9854 | AK18: 1086.8471 | AM18: 1101.2236 | AO18: 1108.7978 | AQ18: 1104.7933 | AS18: 1119.9822 | AU18: 1103.3428 | AW18: 1128.5562 | AY18: 1145.8134 | BA18: 1157.36 | BC18: 1158.4305 | BE18: 1063.5552 | BH18: m | BI18: 1127.6856 | BK18: 1100.9854 | BM18: 1086.8471 | BO18: 1101.2236 | BQ18: 1108.7978 | BS18: 1104.7933 | BU18: 1119.9822 | BW18: 1103.3428 | BY18: 1128.5562 | CA18: 1145.8134 | CC18: 1157.36 | CE18: 1158.4305 | CG18: 1063.5552 | CJ18: m | CK18: 1127.6856 | CM18: 1100.9854 | CO18: 1086.8471 | CQ18: 1101.2236 | CS18: 1108.7978 | CU18: 1104.7933 | CW18: 1119.9822 | CY18: 1103.3428 | DA18: 1128.5562 | DC18: 1145.8134 | DE18: 1157.36 | DG18: 1158.4305 | DI18: 1063.5552
A19: Czech Republic | D19: m | F19: m | H19: m | J19: m | L19: m | N19: m | P19: m | Q19: 1184.2 | S19: 1165.6 | U19: 1165.6 | W19: 1159.4 | Y19: 1159.4 | AA19: 1333 | AC19: 1333 | AF19: m | AG19: 813.4 | AI19: 853.6 | AK19: 849.2 | AM19: 849.2 | AO19: 831.6 | AQ19: 862.4 | AS19: 840.4 | AU19: 827.2 | AW19: 827.2 | AY19: 822.8 | BA19: 822.8 | BC19: 617.1 | BE19: 617.1 | BG19: 650.1 | BI19: 646.8 | BK19: 640.2 | BM19: 636.9 | BO19: 636.9 | BQ19: 623.7 | BS19: 646.8 | BU19: 630.3 | BW19: 620.4 | BY19: 620.4 | CA19: 617.1 | CC19: 617.1 | CE19: 617.1 | CG19: 617.1 | CI19: 620.55 | CK19: 617.4 | CM19: 611.1 | CO19: 607.95 | CQ19: 607.95 | CS19: 595.35 | CU19: 617.4 | CW19: 601.65 | CY19: 592.2 | DA19: 592.2 | DC19: 589.05 | DE19: 589.05 | DG19: 589.05 | DI19: 589.05
A20: Denmark | B20: 2, 3 | D20: m | F20: m | H20: m | J20: m | L20: m | N20: a | P20: a | R20: a | T20: a | V20: a | W20: 1417 | Y20: 1417 | AB20: m | AD20: a | AE20: 640 | AG20: 640 | AI20: 648 | AK20: 648 | AM20: 648 | AO20: 648 | AQ20: 650 | AS20: 650 | AU20: 659 | AW20: 662 | AY20: 663 | BA20: 784 | BB20: b | BD20: a | BF20: a | BG20: 640 | BI20: 640 | BK20: 648 | BM20: 648 | BO20: 648 | BQ20: 648 | BS20: 650 | BU20: 650 | BW20: 659 | BY20: 662 | CA20: 663 | CC20: 784 | CD20: b | CF20: a | CH20: a | CJ20: m | CL20: m | CM20: 364 | CO20: 364 | CQ20: 364 | CS20: 377 | CU20: 377 | CW20: 369 | CY20: 369 | DA20: 369 | DC20: 386 | DE20: 386 | DG20: 394 | DI20: 405
A21: Estonia | D21: m | F21: m | H21: m | J21: m | L21: m | N21: m | P21: m | Q21: 1320 | S21: 1320 | U21: 1320 | W21: 1320 | Y21: 1320 | AA21: 1320 | AC21: 1320 | AE21: 630 | AG21: 630 | AI21: 630 | AK21: 630 | AM21: 630 | AO21: 630 | AQ21: 630 | AS21: 619.2 | AU21: 619.2 | AW21: 619.2 | AY21: 619.2 | BA21: 619.2 | BC21: 584.8 | BE21: 584.8 | BG21: 630 | BI21: 630 | BK21: 630 | BM21: 630 | BO21: 630 | BQ21: 630 | BS21: 630 | BU21: 619.2 | BW21: 619.2 | BY21: 619.2 | CA21: 619.2 | CC21: 619.2 | CE21: 602 | CG21: 602 | CI21: 577.5 | CK21: 577.5 | CM21: 577.5 | CO21: 577.5 | CQ21: 577.5 | CS21: 577.5 | CU21: 577.5 | CW21: 567.6 | CY21: 567.6 | DA21: 567.6 | DC21: 567.6 | DE21: 567.6 | DG21: 567.6 | DI21: 567.6
A22: Finland | D22: m | F22: m | H22: m | J22: m | L22: m | N22: m | P22: m | R22: m | T22: m | V22: m | X22: m | Z22: m | AB22: m | AD22: m | AE22: 655.5 | AG22: 676.8 | AI22: 677 | AK22: 676.8 | AM22: 676.8 | AO22: 676.8 | AQ22: 680.4 | AS22: 680.4 | AU22: 673.2 | AW22: 673.2 | AY22: 673.2 | BA22: 676.8 | BC22: 680.4 | BE22: 673.2 | BG22: 570 | BI22: 592.2 | BK22: 592.2 | BM22: 592.2 | BO22: 592.2 | BQ22: 592.2 | BS22: 595.35 | BU22: 595.35 | BW22: 589.05 | BY22: 589.05 | CA22: 589.05 | CC22: 592.2 | CE22: 595.35 | CG22: 589.05 | CI22: 527.25 | CK22: 550.088 | CM22: 550.088 | CO22: 550.088 | CQ22: 550.088 | CS22: 550.088 | CU22: 553.014 | CW22: 553.014 | CY22: 547.162 | DA22: 547.162 | DC22: 547.162 | DE22: 550.088 | DG22: 553.014 | DI22: 547.162
A23: France | C23: 924 | E23: 924 | G23: 924 | I23: 924 | K23: 924 | M23: 924 | O23: 924 | Q23: 924 | S23: 923.9976 | U23: 924 | W23: 924 | Y23: 899.99995 | AA23: 900 | AC23: 900 | AE23: 924 | AG23: 924 | AI23: 924 | AK23: 924 | AM23: 924 | AO23: 924 | AQ23: 924 | AS23: 924 | AU23: 923.9976 | AW23: 924 | AY23: 924 | BA23: 899.99995 | BC23: 900 | BE23: 900 | BG23: 648 | BI23: 648 | BK23: 648 | BM23: 648 | BO23: 648 | BQ23: 648 | BS23: 648 | BU23: 648 | BW23: 648 | BY23: 648 | CA23: 648 | CC23: 648 | CE23: 684 | CG23: 684 | CI23: 648 | CK23: 648 | CM23: 648 | CO23: 648 | CQ23: 648 | CS23: 648 | CU23: 648 | CW23: 648 | CY23: 648 | DA23: 648 | DC23: 648 | DE23: 648 | DG23: 684 | DI23: 684
A24: Germany | C24: 752.115 | E24: 784.86808 | G24: 817.94367 | I24: 814.98396 | K24: 814.66826 | M24: 805.00615 | O24: 801.91774 | Q24: 800.3224 | S24: 796.26118 | U24: 833.78566 | W24: 1482 | X24: b | Y24: 1482 | AA24: 1755 | AC24: 1755 | AE24: 783.17556 | AG24: 807.54252 | AI24: 809.95918 | AK24: 805.98776 | AM24: 804.81951 | AO24: 804.92987 | AQ24: 804.85896 | AS24: 804.11854 | AU24: 804.34644 | AW24: 799.97541 | AY24: 799.80085 | BA24: 799.32447 | BC24: 801.54522 | BE24: 800.53659 | BG24: 732.28478 | BI24: 758.46457 | BK24: 757.91361 | BM24: 758.08784 | BO24: 756.42666 | BQ24: 756.45788 | BS24: 755.91747 | BU24: 756.76034 | BW24: 755.29321 | BY24: 751.88889 | CA24: 750.08736 | CC24: 750.08736 | CE24: 748.83376 | CG24: 747.40942 | CI24: 689.844 | CK24: 714 | CM24: 713.67453 | CO24: 714.01025 | CQ24: 714.59108 | CS24: 712.82148 | CU24: 713.24753 | CW24: 714.81554 | CY24: 717.50925 | DA24: 714.81111 | DC24: 713.88747 | DE24: 713.88747 | DG24: 716.36861 | DI24: 719.32344
A25: Greece | D25: m | F25: m | H25: m | J25: m | K25: 712 | M25: 708 | O25: 708 | Q25: 708 | S25: 684 | U25: 684 | W25: 684 | Y25: 787.5 | Z25: b | AA25: 792 | AC25: 821.92 | AE25: 608.95686 | AG25: 604.41092 | AI25: 604.41092 | AK25: 590.10653 | AM25: 592.74 | AO25: 589.41 | AQ25: 589.41 | AS25: 589.41 | AU25: 569.43 | AW25: 569.43 | AY25: 569.43 | BA25: 630 | BB25: b | BC25: 660 | BD25: b | BE25: 660 | BG25: 426.02857 | BI25: 434.22143 | BK25: 428.70667 | BM25: 425.99333 | BO25: 428.654 | BQ25: 425.941 | BS25: 415.089 | BU25: 415.089 | BW25: 415.112 | BY25: 415.112 | CA25: 459.04 | CC25: 591.68 | CD25: b | CE25: 584.775 | CF25: b | CG25: 608.925 | CI25: 429.43826 | CK25: 430.44034 | CM25: 420.56667 | CO25: 423.28 | CQ25: 428.654 | CS25: 425.941 | CU25: 415.089 | CW25: 415.089 | CY25: 415.112 | DA25: 415.112 | DC25: 459.04 | DE25: 599.78 | DF25: b | DG25: 592.8825 | DH25: b | DI25: 593.9175
A26: Hungary | D26: m | F26: m | H26: m | J26: m | L26: m | N26: m | P26: m | Q26: 1363.2 | R26: b | S26: 1356.8 | U26: 1318.4 | W26: 1337.6 | Y26: 1337.6 | AA26: 1356.8 | AC26: 1344 | AE26: 583 | AG26: 583 | AI26: 583 | AK26: 582.75 | AM26: 610.5 | AO26: 597.3 | AQ26: 603.9 | AS26: 658.8 | AT26: b | AU26: 658.8 | AW26: 655.2 | AY26: 648 | BA26: 651.6 | BC26: 651.6 | BE26: 655.2 | BG26: 555 | BI26: 555 | BK26: 555 | BM26: 555 | BO26: 610.5 | BQ26: 597.3 | BS26: 603.9 | BU26: 658.8 | BV26: b | BW26: 658.8 | BY26: 655.2 | CA26: 648 | CC26: 651.6 | CE26: 651.6 | CG26: 655.2 | CI26: 555 | CK26: 555 | CM26: 555 | CO26: 555 | CQ26: 610.5 | CS26: 597.3 | CU26: 603.9 | CW26: 655.2 | CX26: b | CY26: 655.2 | DA26: 651.6 | DC26: 644.4 | DE26: 648 | DG26: 648 | DI26: 651.6
A27: Iceland | D27: m | F27: m | H27: m | J27: m | L27: m | N27: m | P27: m | Q27: 1634.4 | S27: 1645.75 | U27: 1498.2 | X27: m | Z27: m | AA27: 1620 | AC27: 1620 | AE27: 629 | AG27: 671.4 | AI27: 671.4 | AK27: 671.4 | AM27: 671.4 | AO27: 624 | AQ27: 623.88 | AS27: 623.88 | AU27: 623.88 | AW27: 623.88 | AZ27: m | BB27: m | BC27: 623.88 | BE27: 623.88 | BG27: 629 | BI27: 671.4 | BK27: 671.4 | BM27: 671.4 | BO27: 671.4 | BQ27: 624 | BS27: 623.88 | BU27: 623.88 | BW27: 623.88 | BY27: 623.88 | CB27: m | CD27: m | CE27: 623.88 | CG27: 623.88 | CI27: 464 | CK27: 560 | CM27: 560 | CO27: 560 | CQ27: 560 | CS27: 544 | CU27: 544 | CW27: 544 | CY27: 544 | DA27: 544 | DD27: m | DF27: m | DG27: 485.39326 | DI27: 485.39326
A28: Ireland | D28: m | F28: m | H28: m | J28: m | L28: m | N28: m | P28: m | R28: m | T28: m | V28: m | X28: m | Z28: m | AB28: m | AD28: m | AE28: 915 | AG28: 915 | AI28: 915 | AK28: 915 | AM28: 915 | AO28: 915 | AQ28: 915 | AS28: 915 | AU28: 915 | AW28: 915 | AY28: 915 | BA28: 915 | BC28: 915 | BE28: 910 | BG28: 734.8 | BI28: 734.8 | BK28: 734.8 | BM28: 734.8 | BO28: 734.8 | BQ28: 734.8 | BS28: 734.8 | BU28: 734.8 | BW28: 734.8 | BY28: 734.8 | CA28: 734.8 | CC28: 734.8 | CE28: 730.4 | CG28: 721.6 | CI28: 734.8 | CK28: 734.8 | CM28: 734.8 | CO28: 734.8 | CQ28: 734.8 | CS28: 734.8 | CU28: 734.8 | CW28: 734.8 | CY28: 734.8 | DA28: 734.8 | DC28: 734.8 | DE28: 734.8 | DG28: 730.4 | DI28: 721.6
A29: Israel | D29: m | F29: m | H29: m | J29: m | L29: m | N29: m | P29: m | Q29: 991.84005 | S29: 1023.4525 | U29: 1031.5236 | W29: 1025.0652 | Y29: 1056.242 | AA29: 1036.1373 | AC29: 1030.7533 | AE29: 731 | AG29: 731 | AI29: 731 | AK29: 731 | AM29: 731 | AO29: 787.998 | AQ29: 819.55312 | AS29: 841.67635 | AU29: 837.83919 | AW29: 839.7828 | AY29: 838.24061 | BA29: 863.61036 | BC29: 848.02609 | BE29: 843.34742 | BG29: 579 | BI29: 579 | BK29: 579 | BM29: 579 | BO29: 579 | BQ29: 589.248 | BS29: 597.9989 | BU29: 614.14527 | BW29: 629.19148 | BY29: 643.55187 | CA29: 681.80737 | CC29: 703.67599 | CE29: 698.15577 | CG29: 698.87171 | CI29: 524 | CK29: 524 | CM29: 524 | CO29: 524 | CQ29: 524 | CS29: 523.952 | CU29: 521.27445 | CW29: 521.28145 | CY29: 557.74536 | DA29: 569.80573 | DC29: 543.07854 | DE29: 586.65496 | DG29: 589.10348 | DI29: 609.74472
A30: Italy | D30: m | F30: m | H30: m | J30: m | L30: m | N30: m | P30: m | Q30: 950 | S30: 930 | U30: 930 | W30: 930 | Y30: 930 | AA30: 945 | AC30: 945 | AE30: 744 | AG30: 739 | AI30: 734.8 | AK30: 734.8 | AM30: 734.8 | AO30: 756.8 | AQ30: 770 | AS30: 770 | AU30: 752.4 | AW30: 752.4 | AY30: 752.4 | BA30: 752.4 | BC30: 765.6 | BE30: 765.6 | BG30: 608 | BI30: 605 | BK30: 601.2 | BM30: 601.2 | BO30: 601.2 | BQ30: 619.2 | BS30: 630 | BU30: 630 | BW30: 615.6 | BY30: 615.6 | CA30: 615.6 | CC30: 615.6 | CE30: 626.4 | CG30: 626.4 | CI30: 608 | CK30: 605 | CM30: 601.2 | CO30: 601.2 | CQ30: 601.2 | CS30: 619.2 | CU30: 630 | CW30: 630 | CY30: 615.6 | DA30: 615.6 | DC30: 615.6 | DE30: 615.6 | DG30: 626.4 | DI30: 626.4
A31: Japan | B31: 4 | D31: m | F31: m | H31: m | J31: m | L31: m | N31: m | P31: m | R31: m | T31: m | V31: m | X31: m | Z31: m | AB31: m | AD31: m | AE31: 635 | AG31: 578 | AI31: m | AK31: 705 | AM31: 708.525 | AO31: 706.7625 | AQ31: 706.7625 | AS31: 731.3595 | AU31: 731.3595 | AW31: 736.2639 | AY31: 742.29885 | BA31: 742.0959 | BC31: 742.0959 | BE31: 742.0959 | BG31: 557 | BI31: 505 | BK31: m | BM31: 600 | BO31: 603 | BQ31: 601.5 | BS31: 601.5 | BU31: 602.41502 | BW31: 602.41502 | BY31: 607.85998 | CA31: 611.24527 | CC31: 609.91057 | CE31: 609.91057 | CG31: 609.91057 | CI31: 478 | CK31: 429 | CN31: m | CO31: 498.3 | CQ31: 500.3465 | CS31: 500.3465 | CU31: 500.3465 | CW31: 509.717 | CY31: 509.717 | DA31: 513.357 | DC31: 513.357 | DE31: 510.757 | DG31: 510.757 | DI31: 510.757
A32: Korea | D32: m | F32: m | H32: m | J32: m | L32: m | N32: m | P32: m | Q32: 679.8 | S32: 583.2 | U32: 574.2 | W32: 584.82 | Y32: 567.86226 | AA32: 554.95046 | AC32: 543.49756 | AE32: 865 | AG32: 883 | AI32: 864 | AK32: 848 | AM32: 840.42988 | AO32: 835.56 | AQ32: 807.4 | AS32: 812.4071 | AU32: 693.5 | AW32: 666.9 | AY32: 655.5 | BA32: 657.82617 | BC32: 657.20642 | BE32: 671.13441 | BG32: 570 | BI32: 621 | BK32: 588 | BM32: 612 | BO32: 616.45693 | BQ32: 618.2 | BS32: 627 | BU32: 620.69221 | BW32: 568.1 | BY32: 556.7 | CA32: 548.34 | CC32: 547.54006 | CE32: 540.45094 | CG32: 533.23146 | CI32: 529.65 | CK32: 605 | CM32: 596.3 | CO32: 599.3 | CQ32: 603.66311 | CS32: 605 | CU32: 616 | CW32: 609.09561 | CY32: 549.1 | DA32: 549.1 | DC32: 549.67 | DE32: 551.01278 | DG32: 551.87125 | DI32: 550.72526
A33: Latvia | D33: m | F33: m | H33: m | J33: m | L33: m | N33: m | P33: m | Q33: 1350 | S33: 1350 | U33: 1260 | X33: m | Y33: 1098 | Z33: b | AA33: 1146 | AC33: 1520 | AE33: 882 | AG33: 882 | AI33: 882 | AK33: 882 | AM33: 882 | AO33: 882 | AQ33: 882 | AS33: 882 | AU33: 882 | AW33: 825 | AZ33: m | BA33: 684.6 | BB33: b | BC33: 718.2 | BE33: 1020 | BG33: 882 | BI33: 882 | BK33: 882 | BM33: 882 | BO33: 882 | BQ33: 882 | BS33: 882 | BU33: 882 | BW33: 882 | BY33: 825 | CB33: m | CC33: 684.6 | CD33: b | CE33: 718.2 | CG33: 1020 | CI33: 882 | CK33: 882 | CM33: 882 | CO33: 882 | CQ33: 882 | CS33: 882 | CU33: 882 | CW33: 882 | CY33: 882 | DA33: 990 | DD33: m | DE33: 684.6 | DF33: b | DG33: 718.2 | DI33: 1020
A34: Luxembourg | D34: m | F34: m | H34: m | J34: m | L34: m | N34: m | P34: m | Q34: 880 | S34: 880 | U34: 880 | W34: 880 | Y34: 880 | AB34: m | AD34: m | AF34: m | AG34: 774.4 | AI34: 774.4 | AK34: 774.4 | AM34: 739.2 | AO34: 739.2 | AQ34: 739.2 | AS34: 809.6 | AU34: 809.6 | AW34: 809.6 | AY34: 809.6 | BA34: 809.6 | BD34: m | BF34: m | BH34: m | BI34: 642.4 | BK34: 642.4 | BM34: 642.4 | BO34: 633.6 | BQ34: 633.6 | BS34: 633.6 | BU34: 739.2 | BW34: 739.2 | BY34: 739.2 | CA34: 739.2 | CC34: 739.2 | CF34: m | CH34: m | CJ34: m | CK34: 642.4 | CM34: 642.4 | CO34: 642.4 | CQ34: 633.6 | CS34: 633.6 | CU34: 633.6 | CW34: 739.2 | CY34: 739.2 | DA34: 739.2 | DC34: 739.2 | DE34: 739.2 | DH34: m | DJ34: m
A35: Mexico | C35: 532 | E35: 532 | G35: 532 | I35: 532 | K35: 532 | M35: 532 | O35: 532 | Q35: 532 | S35: 532 | U35: 532 | W35: 532 | Y35: 532 | AA35: 532 | AC35: 532 | AE35: 800 | AG35: 800 | AI35: 800 | AK35: 800 | AM35: 800 | AO35: 800 | AQ35: 800 | AS35: 800 | AU35: 800 | AW35: 800 | AY35: 800 | BA35: 800 | BC35: 800 | BE35: 800 | BG35: 1182 | BI35: 1046.6667 | BK35: 1046.6667 | BM35: 1046.6667 | BO35: 1046.6667 | BQ35: 1046.6667 | BS35: 1046.6667 | BU35: 1046.6667 | BW35: 1046.6667 | BY35: 1046.6667 | CA35: 1046.6667 | CC35: 1046.6667 | CE35: 1046.6667 | CG35: 1046.6667 | CJ35: m | CK35: 847.7 | CM35: 842.8 | CO35: 842.8 | CQ35: 847.7 | CS35: 842.8 | CU35: 842.8 | CW35: 847.7 | CY35: 837.9 | DA35: 837.9 | DC35: 847.7 | DE35: 847.7 | DG35: 857.5 | DI35: 837.9
A36: Netherlands | D36: m | F36: m | H36: m | J36: m | L36: m | N36: m | P36: m | Q36: 930 | S36: 930 | U36: 930 | W36: 930 | Y36: 930 | AA36: 930 | AC36: 930 | AE36: 930 | AG36: 930.15 | AI36: 930.15 | AK36: 930.15 | AM36: 930.15 | AO36: 930 | AQ36: 930 | AS36: 930 | AU36: 930 | AW36: 930 | AY36: 930 | BA36: 930 | BC36: 930 | BE36: 930 | BG36: 867 | BI36: 750 | BK36: 750 | BM36: 750 | BO36: 750 | BQ36: 750 | BS36: 750 | BU36: 750 | BW36: 750 | BY36: 750 | CA36: 750 | CC36: 750 | CE36: 750 | CG36: 750 | CI36: 867 | CK36: 750 | CM36: 750 | CO36: 750 | CQ36: 750 | CS36: 750 | CU36: 750 | CW36: 750 | CY36: 750 | DA36: 750 | DC36: 750 | DE36: 750 | DG36: 750 | DI36: 750
A37: New Zealand | D37: m | F37: m | H37: m | J37: m | L37: m | N37: m | P37: m | R37: m | T37: m | V37: m | X37: m | Z37: m | AB37: m | AD37: m | AF37: m | AH37: m | AJ37: m | AL37: m | AN37: m | AP37: m | AR37: m | AT37: m | AV37: m | AW37: 921.6 | AY37: 921.6 | BA37: 921.6 | BC37: 921.6 | BE37: 921.6 | BH37: m | BJ37: m | BL37: m | BN37: m | BP37: m | BR37: m | BT37: m | BV37: m | BX37: m | BY37: 840.8 | CA37: 840.4 | CC37: 840.4 | CE37: 840.4 | CG37: 840.4 | CJ37: m | CL37: m | CN37: m | CP37: m | CR37: m | CT37: m | CV37: m | CX37: m | CZ37: m | DA37: 760 | DC37: 760 | DE37: 760 | DG37: 760 | DI37: 760
A38: Norway | D38: m | F38: m | H38: m | J38: m | L38: m | N38: m | P38: m | Q38: 1507.5 | S38: 1507.5 | U38: 1507.5 | W38: 1507.5 | Z38: a | AB38: a | AD38: a | AE38: 712.5 | AG38: 741 | AI38: 741 | AK38: 741 | AM38: 741 | AO38: 741 | AQ38: 741 | AS38: 741 | AU38: 741 | AW38: 741 | AY38: 741 | BA38: 741 | BC38: 741 | BE38: 741 | BG38: 633.08 | BI38: 655.5 | BK38: 653.6 | BM38: 653.6 | BO38: 653.6 | BQ38: 653.6 | BS38: 653.6 | BU38: 663.1 | BW38: 663.1 | BY38: 663.1 | CA38: 663.1 | CC38: 663.1 | CE38: 663.1 | CG38: 663.1 | CI38: 505 | CK38: 523.6 | CM38: 522.5 | CO38: 522.5 | CQ38: 522.5 | CS38: 522.5 | CU38: 522.5 | CW38: 522.5 | CY38: 522.5 | DA38: 522.5 | DC38: 522.5 | DE38: 522.5 | DG38: 522.5 | DI38: 522.5
A39: Poland | D39: m | F39: m | H39: m | J39: m | K39: 1082.5 | M39: 1095 | O39: 1100 | Q39: 1095 | S39: 1090 | U39: 1080 | W39: 1075 | Y39: 1090 | AA39: 1090 | AC39: 1085 | AF39: m | AH39: m | AJ39: m | AL39: m | AM39: 570 | AO39: 570 | AQ39: 586 | AS39: 564 | AU39: 580 | AW39: 580 | AY39: 570.15 | BA39: 573.3 | BC39: 567 | BE39: 563.85 | BH39: m | BJ39: m | BL39: m | BN39: m | BO39: 486 | BQ39: 483 | BS39: 497 | BU39: 477.9 | BW39: 491 | BY39: 491 | CA39: 483.3 | CC39: 486 | CE39: 480.6 | CG39: 477.9 | CJ39: m | CL39: m | CN39: m | CP39: m | CQ39: 486 | CS39: 486 | CU39: 494 | CW39: 472.5 | CY39: 486 | DA39: 483 | DC39: 477.9 | DE39: 480.6 | DG39: 475.2 | DI39: 472.5
A40: Portugal | C40: 1035 | E40: 975 | G40: 935 | I40: 930 | K40: 930 | M40: 950 | O40: 955 | Q40: 965 | S40: 970 | U40: 960 | W40: 945 | Y40: 955 | AA40: 930 | AC40: 935 | AE40: 778.5 | AG40: 765 | AI40: 774 | AK40: 769.5 | AM40: 769.5 | AO40: 787.5 | AQ40: 778.5 | AS40: 792 | AU40: 756 | AW40: 747 | AY40: 742.5 | BA40: 742.5 | BC40: 742.5 | BE40: 778.5 | BG40: 634.33333 | BI40: 623.33333 | BK40: 630.66667 | BM40: 627 | BO40: 627 | BQ40: 641.66667 | BS40: 634.33333 | BU40: 645.33333 | BW40: 616 | BY40: 608.66667 | CA40: 605 | CC40: 605 | CE40: 605 | CG40: 616 | CI40: 576.66667 | CK40: 566.66667 | CM40: 573.33333 | CO40: 627 | CQ40: 627 | CS40: 641.66667 | CU40: 634.33333 | CW40: 645.33333 | CY40: 616 | DA40: 608.66667 | DC40: 605 | DE40: 605 | DG40: 605 | DI40: 616
A41: Slovak Republic | D41: m | F41: m | H41: m | J41: m | L41: m | N41: m | P41: m | Q41: 1127 | S41: 1114 | U41: 1108.8 | W41: 1108.8 | Y41: 1142.4 | AA41: 1160.5 | AC41: 1149.5 | AF41: m | AH41: m | AJ41: m | AL41: m | AN41: m | AO41: 832.15 | AQ41: 841.05 | AS41: 845.5 | AU41: 818.8 | AW41: 832.15 | AY41: 827.7 | BA41: 832.15 | BC41: 802.2 | BE41: 793.8 | BH41: m | BJ41: m | BL41: m | BN41: m | BP41: m | BQ41: 645.15 | BS41: 652.05 | BU41: 655.5 | BW41: 634.8 | BY41: 645.15 | CA41: 641.7 | CC41: 645.15 | CE41: 658.95 | CG41: 652.05 | CJ41: m | CL41: m | CN41: m | CP41: m | CR41: m | CS41: 617.1 | CU41: 623.7 | CW41: 627 | CY41: 607.2 | DA41: 617.1 | DC41: 613.8 | DE41: 617.1 | DG41: 573 | DI41: 567
A42: Slovenia | D42: m | F42: m | H42: m | J42: m | L42: m | N42: m | P42: m | Q42: 1314 | S42: 1314 | U42: 1314 | W42: 1314 | Y42: 1314 | AA42: 1314 | AC42: 1314 | AF42: m | AG42: 627 | AI42: 627 | AK42: 627 | AM42: 627 | AO42: 627 | AQ42: 627 | AS42: 627 | AU42: 627 | AW42: 627 | AY42: 627 | BA42: 627 | BC42: 627 | BE42: 627 | BH42: m | BI42: 627 | BK42: 627 | BM42: 627 | BO42: 627 | BQ42: 627 | BS42: 627 | BU42: 627 | BW42: 627 | BY42: 627 | CA42: 627 | CC42: 627 | CE42: 627 | CG42: 627 | CJ42: m | CK42: 570 | CM42: 570 | CO42: 570 | CQ42: 570 | CS42: 570 | CU42: 570 | CW42: 570 | CY42: 570 | DA42: 570 | DC42: 570 | DE42: 570 | DG42: 570 | DI42: 570
...

Sheet Table D4.3.
A1: Education at a Glance 2018: OECD Indicators - © OECD 2018
A2: D | B2: Indicator D4. How much time do teachers spend teaching?
A3: Version 2 - Last updated: 05-Sep-2018
A4: Disclaimer: http://oe.cd/disclaimer
A6: Table D4.3.
A7: Tasks and responsibilities of teachers, by level of education (2017)
A8: Teachers' tasks and responsibilities in public institutions as defined explicitly in regulations and/or steering documents
B10: Notes | C10: Level of education | D10: Tasks | K10: Other responsibilities
D11: Teaching | E11: Individual planning or preparation of lessons either at school or elsewhere | F11: Marking/correcting of student work | G11: General administrative work (including communication, paperwork and other clerical duties undertaken as part the job) | H11: Communication and co-operation with parents or guardians | I11: Supervision of students during breaks | J11: Team work and dialogue with colleagues at school or elsewhere | K11: Participation in school or other management in addition to teaching duties (e.g. serving as head of department or co-ordinator of teachers) | L11: Teaching more classes or hours than required by full-time contract (e.g. overtime compensation) | M11: Students counselling (including student supervising, virtual counselling, career guidance, and delinquency prevention) | N11: Engaging in extracurricular activities (e.g. homework clubs, sports and drama clubs, summer school) | O11: Special tasks (e.g. training student teachers, guidance counselling) | P11: Class teacher/form teacher | Q11: Participation in mentoring programmes and/or supporting new teachers in induction programmes | R11: Participation in professional development activities
D12: 1 | E12: 2 | F12: 3 | G12: 4 | H12: 5 | I12: 6 | J12: 7 | K12: 8 | L12: 9 | M12: 10 | N12: 11 | O12: 12 | P12: 13 | Q12: 14 | R12: 15
A13: OECD
A14: Countries
A15: Australia | C15: Pre-primary | D15: Mand. | E15: Mand. | F15: Mand. | G15: Mand. | H15: Mand. | I15: Mand. | J15: Mand. | K15: School req. | L15: Not req. | M15: Voluntary | N15: Voluntary | O15: School req. | P15: School req. | Q15: Voluntary | R15: School req.
A16: Australia | C16: Primary | D16: Mand. | E16: Mand. | F16: Mand. | G16: Mand. | H16: Mand. | I16: Mand. | J16: Mand. | K16: School req. | L16: Not req. | M16: Voluntary | N16: Voluntary | O16: School req. | P16: School req. | Q16: Voluntary | R16: School req.
A17: Australia | C17: Lower secondary (gen. progr.) | D17: Mand. | E17: Mand. | F17: Mand. | G17: Mand. | H17: Mand. | I17: Mand. | J17: Mand. | K17: School req. | L17: Not req. | M17: Voluntary | N17: Voluntary | O17: School req. | P17: School req. | Q17: Voluntary | R17: School req.
A18: Australia | C18: Lower secondary (voc. progr.) | D18: Mand. | E18: Mand. | F18: Mand. | G18: Mand. | H18: Mand. | I18: Mand. | J18: Mand. | K18: School req. | L18: Not req. | M18: Voluntary | N18: Voluntary | O18: School req. | P18: School req. | Q18: Voluntary | R18: School req.
A19: Australia | C19: Upper secondary (gen. progr.) | D19: Mand. | E19: Mand. | F19: Mand. | G19: Mand. | H19: Mand. | I19: Mand. | J19: Mand. | K19: School req. | L19: Not req. | M19: Voluntary | N19: Voluntary | O19: School req. | P19: School req. | Q19: Voluntary | R19: School req.
A20: Australia | C20: Upper secondary (voc. progr.) | D20: Mand. | E20: Mand. | F20: Mand. | G20: Mand. | H20: Mand. | I20: Mand. | J20: Mand. | K20: School req. | L20: Not req. | M20: Voluntary | N20: Voluntary | O20: School req. | P20: School req. | Q20: Voluntary | R20: School req.
A21: Austria | C21: Pre-primary | D21: m | E21: m | F21: m | G21: m | H21: m | I21: m | J21: m | K21: m | L21: m | M21: m | N21: m | O21: m | P21: m | Q21: m | R21: m
A22: Austria | C22: Primary | D22: Mand. | E22: Mand. | F22: Mand. | G22: Mand. | H22: Mand. | I22: Mand. | J22: Mand. | K22: Not req. | L22: Mand. | M22: Not req. | N22: Voluntary | O22: Voluntary | P22: Mand. | Q22: Voluntary | R22: Mand.
A23: Austria | C23: Lower secondary (gen. progr.) | D23: Mand. | E23: Mand. | F23: Mand. | G23: Mand. | H23: Mand. | I23: Mand. | J23: Mand. | K23: School req. | L23: Mand. | M23: School req. | N23: Voluntary | O23: Voluntary | P23: School req. | Q23: Voluntary | R23: Mand.
A24: Austria | C24: Lower secondary (voc. progr.) | D24: a | E24: a | F24: a | G24: a | H24: a | I24: a | J24: a | K24: a | L24: a | M24: a | N24: a | O24: a | P24: a | Q24: a | R24: a
A25: Austria | C25: Upper secondary (gen. progr.) | D25: Mand. | E25: Mand. | F25: Mand. | G25: Mand. | H25: Mand. | I25: Mand. | J25: Mand. | K25: School req. | L25: Mand. | M25: School req. | N25: Voluntary | O25: Voluntary | P25: School req. | Q25: Voluntary | R25: Mand.
A26: Austria | C26: Upper secondary (voc. progr.) | D26: Mand. | E26: Mand. | F26: Mand. | G26: Mand. | H26: Mand. | I26: Mand. | J26: Mand. | K26: School req. | L26: Mand. | M26: School req. | N26: Voluntary | O26: Voluntary | P26: School req. | Q26: Voluntary | R26: Mand.
... A148: New Zealand | C148: Primary | D148: Mand. | E148: Mand. | F148: Mand. | G148: Mand. | H148: Mand. | I148: School req. | J148: Mand. | K148: School req. | L148: a | M148: Mand. | N148: Voluntary | O148: School req. | P148: School req. | Q148: School req. | R148: School req.
A149: New Zealand | B149: 1 | C149: Lower secondary (gen. progr.) | D149: Mand. | E149: Mand. | F149: Mand. | G149: Mand. | H149: Mand. | I149: School req. | J149: Mand. | K149: School req. | L149: School req. | M149: Mand./School req. | N149: Voluntary | O149: School req. | P149: School req. | Q149: School req. | R149: School req.
A150: New Zealand | C150: Lower secondary (voc. progr.) | D150: a | E150: a | F150: a | G150: a | H150: a | I150: a | J150: a | K150: a | L150: a | M150: a | N150: a | O150: a | P150: a | Q150: a | R150: a
A151: New Zealand | C151: Upper secondary (gen. progr.) | D151: Mand. | E151: Mand. | F151: Mand. | G151: Mand. | H151: Mand. | I151: School req. | J151: Mand. | K151: School req. | L151: School req. | M151: School req. | N151: Voluntary | O151: School req. | P151: School req. | Q151: School req. | R151: School req.
A152: New Zealand | C152: Upper secondary (voc. progr.) | D152: m | E152: m | F152: m | G152: m | H152: m | I152: m | J152: m | K152: m | L152: m | M152: m | N152: m | O152: m | P152: m | Q152: m | R152: m
A153: Norway | C153: Pre-primary | D153: m | E153: m | F153: m | G153: m | H153: m | I153: m | J153: m | K153: m | L153: m | M153: m | N153: m | O153: m | P153: m | Q153: m | R153: m
A154: Norway | C154: Primary | D154: Mand. | E154: Mand. | F154: Mand. | G154: Mand. | H154: Mand. | I154: School req. | J154: Mand. | K154: School req. | L154: School req. | M154: School req. | N154: Not req. | O154: Voluntary | P154: School req. | Q154: Voluntary | R154: Voluntary
A155: Norway | C155: Lower secondary (gen. progr.) | D155: Mand. | E155: Mand. | F155: Mand. | G155: Mand. | H155: Mand. | I155: School req. | J155: Mand. | K155: School req. | L155: School req. | M155: School req. | N155: Not req. | O155: Voluntary | P155: School req. | Q155: Voluntary | R155: Voluntary
A156: Norway | C156: Lower secondary (voc. progr.) | D156: a | E156: a | F156: a | G156: a | H156: a | I156: a | J156: a | K156: a | L156: a | M156: a | N156: a | O156: a | P156: a | Q156: a | R156: a
A157: Norway | C157: Upper secondary (gen. progr.) | D157: Mand. | E157: Mand. | F157: Mand. | G157: Mand. | H157: Mand. | I157: School req. | J157: Mand. | K157: School req. | L157: School req. | M157: School req. | N157: Not req. | O157: Voluntary | P157: School req. | Q157: Voluntary | R157: Voluntary
A158: Norway | C158: Upper secondary (voc. progr.) | D158: Mand. | E158: Mand. | F158: Mand. | G158: Mand. | H158: Mand. | I158: School req. | J158: Mand. | K158: School req. | L158: School req. | M158: School req. | N158: Not req. | O158: Voluntary | P158: School req. | Q158: Voluntary | R158: Voluntary
A159: Poland | C159: Pre-primary | D159: Mand. | E159: Mand. | F159: Mand. | G159: Mand. | H159: Mand. | I159: Mand. | J159: Mand. | K159: School req. | L159: Mand. | M159: Not req. | N159: Voluntary | O159: Voluntary | P159: School req. | Q159: Voluntary | R159: Mand.
A160: Poland | C160: Primary | D160: Mand. | E160: Mand. | F160: Mand. | G160: Mand. | H160: Mand. | I160: Mand. | J160: Mand. | K160: School req. | L160: Voluntary | M160: Not req. | N160: Voluntary | O160: Voluntary | P160: School req. | Q160: Voluntary | R160: Mand.
A161: Poland | C161: Lower secondary (gen. progr.) | D161: Mand. | E161: Mand. | F161: Mand. | G161: Mand. | H161: Mand. | I161: Mand. | J161: Mand. | K161: School req. | L161: Voluntary | M161: Not req. | N161: Voluntary | O161: Voluntary | P161: School req. | Q161: Voluntary | R161: Mand.
... A212: United States | C212: Upper secondary (voc. progr.) | D212: Mand. | E212: School Req. | F212: School Req. | G212: School Req. | H212: School Req. | I212: School Req. | J212: School Req. | K212: School Req. | L212: School Req. | M212: School Req. | N212: School Req. | O212: School Req. | P212: School Req. | Q212: School Req. | R212: School Req.
A214: Economies
...

Sheet Figure D4.1.
A1: Education at a Glance 2018: OECD Indicators - © OECD 2018
A2: D | B2: Indicator D4. How much time do teachers spend teaching?
A3: Version 2 - Last updated: 05-Sep-2018
A4: Disclaimer: http://oe.cd/disclaimer
A6: Figure D4.1.
A7: Number of teaching hours per year in general lower secondary education (2000, 2005 and 2017)
A8: Net statutory contact time in public institutions
A35: Note: The OECD average refers to OECD countries and economies with available data for 2005, 2010, 2015 and 2017.
A36: 1. Actual teaching time.
A37: 2. Year of reference 2016 instead of 2017.
A38: 3. Average planned teaching time in each school at the beginning of the school year.
A39: Countries and economies are ranked in descending order of the number of teaching hours per year in general lower secondary education in 2017.
A40: Source: OECD (2018), Table D4.2. See Source section for more information and Annex 3 for notes (http://dx.doi.org/10.1787/eag-2018-36-en).
A41: Lithuania was not an OECD Member at the time of preparation of this publication. Accordingly, Lithuania does not appear in the list of OECD Members and is not included in the zone aggregates. OECD and EU23 averages including Lithuania have been added at the end of this table for information purposes.
B46: 2005 | C46: 2000 | D46: 2017
A47: Costa Rica | D47: 1267.2
A48: Colombia | B48: 1200 | D48: 1200
A49: Chile | B49: 1127.6856 | D49: 1063.5552
A50: Mexico | B50: 1046.6667 | C50: 1182 | D50: 1046.6667
A51: Latvia | B51: 882 | C51: 882 | D51: 1020
A52: United States1, 2 | D52: 966.36312
A53: Scotland (UK) | B53: 893 | C53: 893 | D53: 855
A54: New Zealand | D54: 840.4
A55: Australia | B55: 810.16 | C55: 810.54626 | D55: 797.28162
A56: Switzerland | D56: 760
A57: Netherlands | B57: 750 | C57: 867 | D57: 750
A58: Germany | B58: 758.46457 | C58: 732.28478 | D58: 747.40942
A59: Canada | D59: 744.53292
A60: Ireland | B60: 734.8 | C60: 734.8 | D60: 721.6
A61: Spain | B61: 712.8 | C61: 713 | D61: 712.8
A62: Israel | B62: 579 | C62: 579 | D62: 698.87171
A63: OECD average | B63: 673.43243 | C63: 681.79013 | D63: 696.15802
A64: France | B64: 648 | C64: 648 | D64: 684
A65: Norway | B65: 655.5 | C65: 633.08 | D65: 663.1
A66: French comm. (Belgium) | B66: 662 | C66: 662 | D66: 656.93
A67: Hungary | B67: 555 | C67: 555 | D67: 655.2
A68: Slovak Republic | D68: 652.05
A69: Slovenia | B69: 627 | D69: 627
A70: Italy | B70: 605 | C70: 608 | D70: 626.4
A71: Iceland | B71: 671.4 | C71: 629 | D71: 623.88
...

Sheet Figure D4.2.
A1: Education at a Glance 2018: OECD Indicators - © OECD 2018
A2: D | B2: Indicator D4. How much time do teachers spend teaching?
A3: Version 2 - Last updated: 05-Sep-2018
A4: Disclaimer: http://oe.cd/disclaimer
A6: Figure D4.2.
A7: Number of teaching hours per year, by level of education (2017)
A8: Net statutory contact time in public institutions
A37: 1. Actual teaching time.
A38: 2. Year of reference 2016.
A39: 3. Average planned teaching time in each school at the beginning of the school year.
A40: Countries and economies are ranked in descending order of the number of teaching hours per year in general upper secondary education.
A41: Source: OECD (2018), Table D4.1. See Source section for more information and Annex 3 for notes (http://dx.doi.org/10.1787/eag-2018-36-en).
A42: Lithuania was not an OECD Member at the time of preparation of this publication. Accordingly, Lithuania does not appear in the list of OECD Members and is not included in the zone aggregates. OECD and EU23 averages including Lithuania have been added at the end of this table for information purposes.
B47: Upper secondary, general programmes | C47: Lower secondary, general programmes | D47: Primary | E47: Pre-primary
A48: Costa Rica | B48: 1267.2 | C48: 1267.2 | D48: 1188 | E48: 811.8
A49: Colombia | B49: 1200 | C49: 1200 | D49: 1000 | E49: 800
A50: Chile | B50: 1063.5552 | C50: 1063.5552 | D50: 1063.5552 | E50: 1063.5552
A51: Latvia | B51: 1020 | C51: 1020 | D51: 1020 | E51: 1520
A52: United States1, 2 | B52: 965.67012 | C52: 966.36312 | D52: 1004.3748 | E52: 1010.709
A53: Scotland (UK) | B53: 855 | C53: 855 | D53: 855 | E53: 855
A54: Mexico | B54: 837.9 | C54: 1046.6667 | D54: 800 | E54: 532
A55: Australia | B55: 797.28162 | C55: 797.28162 | D55: 865.2686 | E55: 903.24667
A56: New Zealand | B56: 760 | C56: 840.4 | D56: 921.6
A57: Netherlands | B57: 750 | C57: 750 | D57: 930 | E57: 930
A58: Canada | B58: 745.74031 | C58: 744.53292 | D58: 797.7713
A59: Ireland | B59: 721.6 | C59: 721.6 | D59: 910
A60: Germany | B60: 719.32344 | C60: 747.40942 | D60: 800.53659 | E60: 1755
A61: Spain | B61: 692.55 | C61: 712.8 | D61: 880 | E61: 880
A62: France | B62: 684 | C62: 684 | D62: 900 | E62: 900
A63: OECD average | B63: 656.77701 | C63: 703.36639 | D63: 783.63764 | E63: 1044.2226
A64: Hungary | B64: 651.6 | C64: 655.2 | D64: 655.2 | E64: 1344
A65: Switzerland | B65: 646 | C65: 760 | D65: 817 | E65: 779
A66: EU22 average | B66: 634.8167 | C66: 667.96489 | D66: 762.45072 | E66: 1093.3545
A67: Italy | B67: 626.4 | C67: 626.4 | D67: 765.6 | E67: 945
A68: Portugal | B68: 616 | C68: 616 | D68: 778.5 | E68: 935
A69: Israel | B69: 609.74472 | C69: 698.87171 | D69: 843.34742 | E69: 1030.7533
A70: Lithuania | B70: 603 | C70: 612 | D70: 576 | E70: 640
A71: French comm. (Belgium) | B71: 596.07 | C71: 656.93 | D71: 716 | E71: 775.07
... A73: Czech Republic | B73: 589.05 | C73: 617.1 | D73: 617.1 | E73: 1333
A74: Austria | B74: 588.6 | C74: 606.6 | D74: 779.4
...

Sheet Figure D4.3.
A1: Education at a Glance 2018: OECD Indicators - © OECD 2018
A2: D | B2: Indicator D4. How much time do teachers spend teaching?
A3: Version 2 - Last updated: 05-Sep-2018
A4: Disclaimer: http://oe.cd/disclaimer
A6: Figure D4.3.
A7: Number of teaching hours per year in general and vocational programmes at upper secondary level (2017)
A8: Net statutory contact time in public institutions
A37: 1. Average planned teaching time in each school at the beginning of the school year.
A38: Countries and economies are ranked in descending order of the number of teaching hours per year in general upper secondary education.
A39: Source: OECD (2018), Table D4.1. See Source section for more information and Annex 3 for notes (http://dx.doi.org/10.1787/eag-2018-36-en).
A40: Lithuania was not an OECD Member at the time of preparation of this publication. Accordingly, Lithuania does not appear in the list of OECD Members and is not included in the zone aggregates. OECD and EU23 averages including Lithuania have been added at the end of this table for information purposes.
B45: Upper secondary, vocational programmes | C45: Upper secondary, general programmes
A46: Costa Rica | B46: 1267.2 | C46: 1267.2
A47: Colombia | B47: 1200 | C47: 1200
A48: Chile | B48: 1063.5552 | C48: 1063.5552
A49: Latvia | B49: 1290 | C49: 1020
A50: Mexico | B50: 684 | C50: 837.9
A51: Canada | B51: 635 | C51: 745.74031
A52: Germany | B52: 726.1909 | C52: 719.32344
A53: Spain | B53: 692.55 | C53: 692.55
A54: France | B54: 684 | C54: 684
A55: OECD average | B55: 655.81928 | C55: 656.77701
A56: Hungary | B56: 651.6 | C56: 651.6
A57: Switzerland | B57: 741 | C57: 646
... A78: EU23 average incl. Lithuania | B78: 673.8528 | C78: 633.37049

Sheet Figure D4.4.
A1: Education at a Glance 2018: OECD Indicators - © OECD 2018
A2: D | B2: Indicator D4. How much time do teachers spend teaching?
A3: Version 2 - Last updated: 05-Sep-2018
A4: Disclaimer: http://oe.cd/disclaimer
A6: Figure D4.4.
A7: Percentage of lower secondary teachers' working time spent teaching (2017)
A8: Net teaching time (typical annual number of hours) as a percentage of total statutory working time in general programmes in public institutions
A33: 1. Average planned teaching time in each school at the beginning of the school year.
A34: 2. Actual teaching time.
A35: 3. Year of reference 2016 instead of 2017.
A36: Source: OECD (2018), Table D4.1. See Source section for more information and Annex 3 for notes (http://dx.doi.org/10.1787/eag-2018-36-en).
A37: Lithuania was not an OECD Member at the time of preparation of this publication. Accordingly, Lithuania does not appear in the list of OECD Members and is not included in the zone aggregates. OECD and EU23 averages including Lithuania have been added at the end of this table for information purposes.
B42: Net teaching time in hours | C42: Percentage of total statutory working time spent teaching
A43: Poland | B43: 477.9 | C43: 0.32290541
A44: Turkey | B44: 504 | C44: 0.31658291
A45: Korea | B45: 533.23146 | C45: 0.35081017
A46: Estonia | B46: 602 | C46: 0.39090909
A47: Austria | B47: 606.6 | C47: 0.34155405
A48: Japan1 | B48: 609.91057 | C48: 0.32390365
A49: Lithuania | B49: 612 | C49: 0.38636364
A50: Czech Republic | B50: 617.1 | C50: 0.39557692
A51: Iceland | B51: 623.88 | C51: 0.35447727
A52: Portugal | B52: 616 | C52: 0.42249657
A53: Slovak Republic | B53: 652.05 | C53: 0.41598086
A54: Hungary | B54: 655.2 | C54: 0.39375
... A67: Country average | B67: 717.95715 | C67: 0.43857317

Sheet Statutory vs actual
A1: Comparison between statutory versus actual (including extra-hours) teaching time
C5: Primary | D5: Lower secondary | E5: Upper secondary
B6: Notes | C6: Difference in teaching time | D6: Difference in teaching time | E6: Difference in teaching time
C7: (1) | D7: (3) | E7: (5)
A8: OECD
A9: Australia | C9: =IF(COUNT('Table D4.1.'!AC15,#REF!)=2,#REF!/'Table D4.1.'!AC15,"m") -> m | D9: =IF(COUNT('Table D4.1.'!AE15,#REF!)=2,#REF!/'Table D4.1.'!AE15,"m") -> m | E9: =IF(COUNT('Table D4.1.'!AI15,#REF!)=2,#REF!/'Table D4.1.'!AI15,"m") -> m
A10: Austria | C10: =IF(COUNT('Table D4.1.'!AC16,#REF!)=2,#REF!/'Table D4.1.'!AC16,"m") -> m | D10: =IF(COUNT('Table D4.1.'!AE16,#REF!)=2,#REF!/'Table D4.1.'!AE16,"m") -> m | E10: =IF(COUNT('Table D4.1.'!AI16,#REF!)=2,#REF!/'Table D4.1.'!AI16,"m") -> m
A11: Belgium (Fl.) | C11: =IF(COUNT('Table D4.1.'!AC50,#REF!)=2,#REF!/'Table D4.1.'!AC50,"m") -> m | D11: =IF(COUNT('Table D4.1.'!AE50,#REF!)=2,#REF!/'Table D4.1.'!AE50,"m") -> m | E11: =IF(COUNT('Table D4.1.'!AI50,#REF!)=2,#REF!/'Table D4.1.'!AI50,"m") -> m
A12: Belgium (Fr.) | C12: =IF(COUNT('Table D4.1.'!AC51,#REF!)=2,#REF!/'Table D4.1.'!AC51,"m") -> m | D12: =IF(COUNT('Table D4.1.'!AE51,#REF!)=2,#REF!/'Table D4.1.'!AE51,"m") -> m | E12: =IF(COUNT('Table D4.1.'!AI51,#REF!)=2,#REF!/'Table D4.1.'!AI51,"m") -> m
A13: Canada | C13: =IF(COUNT('Table D4.1.'!AC17,#REF!)=2,#REF!/'Table D4.1.'!AC17,"m") -> m | D13: =IF(COUNT('Table D4.1.'!AE17,#REF!)=2,#REF!/'Table D4.1.'!AE17,"m") -> m | E13: =IF(COUNT('Table D4.1.'!AI17,#REF!)=2,#REF!/'Table D4.1.'!AI17,"m") -> m
A14: Chile | C14: =IF(COUNT('Table D4.1.'!AC18,#REF!)=2,#REF!/'Table D4.1.'!AC18,"m") -> m | D14: =IF(COUNT('Table D4.1.'!AE18,#REF!)=2,#REF!/'Table D4.1.'!AE18,"m") -> m | E14: =IF(COUNT('Table D4.1.'!AI18,#REF!)=2,#REF!/'Table D4.1.'!AI18,"m") -> m
A15: Czech Republic | C15: =IF(COUNT('Table D4.1.'!AC19,#REF!)=2,#REF!/'Table D4.1.'!AC19,"m") -> m | D15: =IF(COUNT('Table D4.1.'!AE19,#REF!)=2,#REF!/'Table D4.1.'!AE19,"m") -> m | E15: =IF(COUNT('Table D4.1.'!AI19,#REF!)=2,#REF!/'Table D4.1.'!AI19,"m") -> m
A16: Denmark | C16: =IF(COUNT('Table D4.1.'!AC20,#REF!)=2,#REF!/'Table D4.1.'!AC20,"m") -> m | D16: =IF(COUNT('Table D4.1.'!AE20,#REF!)=2,#REF!/'Table D4.1.'!AE20,"m") -> m | E16: =IF(COUNT('Table D4.1.'!AI20,#REF!)=2,#REF!/'Table D4.1.'!AI20,"m") -> m
A17: England | C17: =IF(COUNT('Table D4.1.'!AC52,#REF!)=2,#REF!/'Table D4.1.'!AC52,"m") -> m | D17: =IF(COUNT('Table D4.1.'!AE52,#REF!)=2,#REF!/'Table D4.1.'!AE52,"m") -> m | E17: =IF(COUNT('Table D4.1.'!AI52,#REF!)=2,#REF!/'Table D4.1.'!AI52,"m") -> m
A18: Estonia | C18: =IF(COUNT('Table D4.1.'!AC21,#REF!)=2,#REF!/'Table D4.1.'!AC21,"m") -> m | D18: =IF(COUNT('Table D4.1.'!AE21,#REF!)=2,#REF!/'Table D4.1.'!AE21,"m") -> m | E18: =IF(COUNT('Table D4.1.'!AI21,#REF!)=2,#REF!/'Table D4.1.'!AI21,"m") -> m
A19: Finland | C19: =IF(COUNT('Table D4.1.'!AC22,#REF!)=2,#REF!/'Table D4.1.'!AC22,"m") -> m | D19: =IF(COUNT('Table D4.1.'!AE22,#REF!)=2,#REF!/'Table D4.1.'!AE22,"m") -> m | E19: =IF(COUNT('Table D4.1.'!AI22,#REF!)=2,#REF!/'Table D4.1.'!AI22,"m") -> m
A20: France | C20: =IF(COUNT('Table D4.1.'!AC23,#REF!)=2,#REF!/'Table D4.1.'!AC23,"m") -> m | D20: =IF(COUNT('Table D4.1.'!AE23,#REF!)=2,#REF!/'Table D4.1.'!AE23,"m") -> m | E20: =IF(COUNT('Table D4.1.'!AI23,#REF!)=2,#REF!/'Table D4.1.'!AI23,"m") -> m
A21: Germany | C21: =IF(COUNT('Table D4.1.'!AC24,#REF!)=2,#REF!/'Table D4.1.'!AC24,"m") -> m | D21: =IF(COUNT('Table D4.1.'!AE24,#REF!)=2,#REF!/'Table D4.1.'!AE24,"m") -> m | E21: =IF(COUNT('Table D4.1.'!AI24,#REF!)=2,#REF!/'Table D4.1.'!AI24,"m") -> m
A22: Greece | C22: =IF(COUNT('Table D4.1.'!AC25,#REF!)=2,#REF!/'Table D4.1.'!AC25,"m") -> m | D22: =IF(COUNT('Table D4.1.'!AE25,#REF!)=2,#REF!/'Table D4.1.'!AE25,"m") -> m | E22: =IF(COUNT('Table D4.1.'!AI25,#REF!)=2,#REF!/'Table D4.1.'!AI25,"m") -> m
A23: Hungary | C23: =IF(COUNT('Table D4.1.'!AC26,#REF!)=2,#REF!/'Table D4.1.'!AC26,"m") -> m | D23: =IF(COUNT('Table D4.1.'!AE26,#REF!)=2,#REF!/'Table D4.1.'!AE26,"m") -> m | E23: =IF(COUNT('Table D4.1.'!AI26,#REF!)=2,#REF!/'Table D4.1.'!AI26,"m") -> m
A24: Iceland | C24: =IF(COUNT('Table D4.1.'!AC27,#REF!)=2,#REF!/'Table D4.1.'!AC27,"m") -> m | D24: =IF(COUNT('Table D4.1.'!AE27,#REF!)=2,#REF!/'Table D4.1.'!AE27,"m") -> m | E24: =IF(COUNT('Table D4.1.'!AI27,#REF!)=2,#REF!/'Table D4.1.'!AI27,"m") -> m
